<?xml version="1.0"?>
<robot xmlns:xacro="http://www.ros.org/wiki/xacro" name="cobra">

    <!-- <link name="world"/>
    <joint name="world_to_base" type="fixed">
        <origin rpy="0 0 0" xyz="0 0 0"/>
        <parent link="world"/>
        <child link="manipulator_link"/>
    </joint> -->

    <!-- MACROS -->

    <xacro:macro name="body_link" params="base_name parent_name colour">
        
        <link name="${base_name}_aux">
            <inertial>
                <origin xyz="0 0 0.025" rpy="0 0 0"/>
                <mass value="0.1" />
                <inertia ixx="0.002" ixy="0.0" ixz="0.0" iyy="0.02" iyz="0.0" izz="0.002"/>
            </inertial>
            <collision>
                <origin xyz="0 0 0.025" rpy="0 0 0"/>
                <geometry>
                    <sphere radius="0.025"/>
                </geometry>
                <self_collide>false</self_collide>
            </collision>
            <visual>
                <origin xyz="0 0 0.025" rpy="0 0 0"/>
                <geometry>
                    <sphere radius="0.05"/>
                </geometry>
            </visual>
    	</link>
    	
    	<gazebo reference="${base_name}_aux">
            <kp>100.0</kp>
            <kd>1.0</kd>
            <mu1>10.0</mu1>
            <mu2>10.0</mu2>
            <material>Gazebo/Black</material>
            <self_collide>1</self_collide>
        </gazebo>
    	
    	
        <link name="${base_name}">
     	    <inertial>
                <origin xyz="0 0 0.075" rpy="0 0 0"/>
                <mass value="0.1" />
                <inertia ixx="0.002" ixy="0.0" ixz="0.0" iyy="0.02" iyz="0.0" izz="0.002"/>
            </inertial>
            <collision>
                <origin xyz="0 0 0.075" rpy="0 0 0"/>
                <geometry>
                    <cylinder radius="0.05" length="0.15"/>
                </geometry>
                <self_collide>false</self_collide>
            </collision>
            <visual>
                <origin xyz="0 0 0.075" rpy="0 0 0"/>
                <geometry>
                    <cylinder radius="0.05" length="0.15"/>
                </geometry>
            </visual>
    	</link>
    	
    	<gazebo reference="${base_name}">
            <kp>100.0</kp>
            <kd>1.0</kd>
            <mu1>1.0</mu1>
            <mu2>1.0</mu2>
            <material>Gazebo/${colour}</material>
            <self_collide>1</self_collide>
        </gazebo>
        
        <!-- We add to the Origin displacement a margin for flex due to self colisions for parent_name and base_name-->
        <joint name="${base_name}_aux_joint" type="revolute">
            <parent link="${parent_name}"/>
        	<child link="${base_name}_aux"/>
            <origin xyz="0 0 0.15" rpy="0 0 0"/>
            <limit lower="-1.5708" upper="1.5708" effort="100.0" velocity="0.5"/>
            <axis xyz="1 0 0"/>
            <dynamics damping="10" friction="10"/>
            <disable_collision>true</disable_collision>
    	</joint>
    	
        <joint name="${base_name}_joint" type="revolute">
    	    <parent link="${base_name}_aux"/>
        	<child link="${base_name}"/>
            <origin xyz="0 0 0.05" rpy="0 0 0"/>
            <limit lower="-1.5708" upper="1.5708" effort="100.0" velocity="0.5"/>
            <axis xyz="0 1 0"/>
            <dynamics damping="10" friction="10"/>
            <disable_collision>true</disable_collision>
    	</joint>
    	
    	
	    <transmission name="tran${base_name}_aux">
            <type>transmission_interface/SimpleTransmission</type>
            <joint name="${base_name}_aux_joint">
                <hardwareInterface>hardware_interface/EffortJointInterface</hardwareInterface>
            </joint>
            <actuator name="motor${base_name}_aux">
                <hardwareInterface>hardware_interface/EffortJointInterface</hardwareInterface>
                <mechanicalReduction>1</mechanicalReduction>
            </actuator>
        </transmission>
        
        <transmission name="tran${base_name}">
            <type>transmission_interface/SimpleTransmission</type>
            <joint name="${base_name}_joint">
                <hardwareInterface>hardware_interface/EffortJointInterface</hardwareInterface>
            </joint>
            <actuator name="motor${base_name}">
                <hardwareInterface>hardware_interface/EffortJointInterface</hardwareInterface>
                <mechanicalReduction>1</mechanicalReduction>
            </actuator>
        </transmission>
    	
    </xacro:macro>
	<!-- * * * Link Definitions * * * -->
	

    <link name="manipulator_link">
 	    <inertial>
            <origin xyz="0 0 0.075" rpy="0 0 0"/>
            <mass value="0.1" />
            <inertia ixx="0.002" ixy="0.0" ixz="0.0" iyy="0.02" iyz="0.0" izz="0.002"/>
        </inertial>
        <collision>
            <origin xyz="0 0 0.075" rpy="0 0 0"/>
            <geometry>
                <cylinder radius="0.05" length="0.15"/>
            </geometry>
        </collision>
        <visual>
            <origin xyz="0 0 0.075" rpy="0 0 0"/>
            <geometry>
                <cylinder radius="0.05" length="0.15"/>
            </geometry>
        </visual>
	</link>



    <gazebo reference="manipulator_link">
        <kp>100000000000000.0</kp>
        <kd>1.0</kd>
        <mu1>1.0</mu1>
        <mu2>1.0</mu2>
        <material>Gazebo/Green</material>
        <self_collide>0</self_collide>
    </gazebo>

    <xacro:body_link base_name="cobra_body_1" parent_name="manipulator_link" colour="Blue"/>
    <xacro:body_link base_name="cobra_body_2" parent_name="cobra_body_1" colour="Blue"/>
    <xacro:body_link base_name="cobra_body_3" parent_name="cobra_body_2" colour="Blue"/>
    <xacro:body_link base_name="cobra_body_4" parent_name="cobra_body_3" colour="Blue"/>
    <xacro:body_link base_name="cobra_body_5" parent_name="cobra_body_4" colour="Blue"/>
    <xacro:body_link base_name="cobra_body_6" parent_name="cobra_body_5" colour="Blue"/>
    <!-- <xacro:body_link base_name="cobra_body_7" parent_name="cobra_body_6" colour="Blue"/> -->
    <!-- <xacro:body_link base_name="cobra_body_8" parent_name="cobra_body_7" colour="Blue"/>
    <xacro:body_link base_name="cobra_body_9" parent_name="cobra_body_8" colour="Blue"/>
    <xacro:body_link base_name="cobra_body_10" parent_name="cobra_body_9" colour="Blue"/>
    <xacro:body_link base_name="cobra_body_11" parent_name="cobra_body_10" colour="Blue"/>
    <xacro:body_link base_name="cobra_body_12" parent_name="cobra_body_11" colour="Blue"/>
    <xacro:body_link base_name="cobra_body_13" parent_name="cobra_body_12" colour="Blue"/>

    <xacro:body_link base_name="cobra_body_22" parent_name="cobra_body_13" colour="Blue"/>
    <xacro:body_link base_name="cobra_body_32" parent_name="cobra_body_22" colour="Blue"/>
    <xacro:body_link base_name="cobra_body_42" parent_name="cobra_body_32" colour="Blue"/>
    <xacro:body_link base_name="cobra_body_52" parent_name="cobra_body_42" colour="Blue"/>
    <xacro:body_link base_name="cobra_body_62" parent_name="cobra_body_52" colour="Blue"/>
    <xacro:body_link base_name="cobra_body_72" parent_name="cobra_body_62" colour="Blue"/>
    <xacro:body_link base_name="cobra_body_82" parent_name="cobra_body_72" colour="Blue"/>
    <xacro:body_link base_name="cobra_body_92" parent_name="cobra_body_82" colour="Blue"/> -->

    <joint name="camera_joint" type="fixed">
        <origin xyz="0.0 0 0.175" rpy="0 -1.57 -1.57"/>
        <parent link="cobra_body_6"/>
        <child link="camera_link"/>        
    </joint>

    <link name="camera_link">
        <inertial>
            <mass value="0.1" />
            <origin xyz="0 0 0" rpy="0 0 0"/>
            <inertia ixx="0.001" ixy="0.0" ixz="0.0" iyy="0.001" iyz="0.0" izz="0.001"/>
        </inertial>
        <visual>
            <origin xyz="-0.03 0 0" rpy="0 0 0"/>
            <geometry>
                <box size="0.03 0.07 0.07" />
            </geometry>
            <material name="white" />
        </visual>
        <visual>
            <origin xyz="0 0 0" rpy="0 ${pi/2} 0"/>
            <geometry>
                <cylinder length="0.03" radius="0.02" />
            </geometry>
            <!-- <material name="blue" /> -->
        </visual>
        <collision>
            <origin xyz="0.0 0 0" rpy="0 0 0"/>
            <geometry>
                <box size="0.03 0.07 0.07" />
            </geometry>
            <self_collide>0</self_collide>
        </collision>
    </link>

    <joint name="camera_optical_joint" type="fixed">
        <origin xyz="0 0 0" rpy="-1.571 0 -1.571" />
        <parent link="camera_link" />
        <child link="camera_link_optical" />
    </joint>

    <link name="camera_link_optical"></link>

    <gazebo reference="camera_link">
        <sensor type="depth" name="my_camera">
            <update_rate>20</update_rate>
            <visualize>true</visualize>
            <camera name="cam">
                <horizontal_fov>1.3962634</horizontal_fov>
                <image>
                    <width>640</width>
                    <height>480</height>
                    <format>R8B8G8</format>
                </image>
                <clip>
                    <near>0.02</near>
                    <far>300</far>
                </clip>
                <noise>
                    <type>gaussian</type>
                    <mean>0.0</mean>
                    <stddev>0.007</stddev>
                </noise>
            </camera>
            <plugin name="camera_controller" filename="libgazebo_ros_camera.so">
                <frame_name>camera_link_optical</frame_name>
                <min_depth>0.1</min_depth>
                <max_depth>500</max_depth>
            </plugin>
        </sensor>
    </gazebo>


    <joint name="imu_joint_manipulator" type="fixed">
        <origin xyz="0.0 0 0.173" rpy="0 0 0" />
        <parent link="cobra_body_6" />
        <child link="imu_link_manipulator" />
    </joint>

    <link name="imu_link_manipulator"></link>

    <gazebo reference="imu_link_manipulator">
      <sensor name="imu_sensor" type="imu">
      <plugin filename="libgazebo_ros_imu_sensor.so" name="imu_plugin_1">
          <ros>
            <remapping>~/out:=imu/data_raw_1</remapping>
          </ros>
          <initial_orientation_as_reference>false</initial_orientation_as_reference>
        </plugin>
        <always_on>true</always_on>
        <update_rate>100</update_rate>
        <visualize>true</visualize>
      </sensor>
    </gazebo>

    <joint name="imu_joint_manipulator_2" type="fixed">
       <origin xyz="0.0 0 0.14" rpy="0 0 0" />
       <parent link="cobra_body_3" />
       <child link="imu_link_manipulator_2" />
    </joint>

    <link name="imu_link_manipulator_2"></link>

    <gazebo reference="imu_link_manipulator_2">
      <sensor name="imu_sensor_2" type="imu">
        <plugin filename="libgazebo_ros_imu_sensor.so" name="imu_plugin_2">
          <ros>
            <remapping>~/out:=imu/data_raw_2</remapping>
          </ros>
          <initial_orientation_as_reference>false</initial_orientation_as_reference>
        </plugin>
        <always_on>true</always_on>
        <update_rate>100</update_rate>
        <visualize>true</visualize>
      </sensor>
    </gazebo>

    

</robot>