<?xml version="1.0" ?>
<robot name="spot_arm" xmlns:xacro="http://www.ros.org/wiki/xacro">

<xacro:include filename="$(find spot_arm_description)/urdf/materials.xacro" />
<xacro:include filename="$(find spot_manipulator_description)/urdf/spot_arm.trans" />
<xacro:include filename="$(find spot_manipulator_description)/urdf/spot_arm.gazebo" />
<link name="manipulator_base">
  <inertial>
    <origin rpy="0 0 0" xyz="1.2371844231029972e-17 0.0 0.0325"/>
    <mass value="0.1"/>
    <inertia ixx="0.0001252" ixy="-0.0" ixz="0.0" iyy="0.0001252" iyz="0.0" izz="0.00018"/>
  </inertial>
  <visual>
    <origin rpy="0 0 0" xyz="0 0 0"/>
    <geometry>
      <mesh filename="package://spot_arm_description/meshes/base_link.stl" scale="0.001 0.001 0.001"/>
    </geometry>
    <material name="silver"/>
  </visual>
  <collision>
    <origin rpy="0 0 0" xyz="0 0 0"/>
    <geometry>
      <mesh filename="package://spot_arm_description/meshes/base_link.stl" scale="0.001 0.001 0.001"/>
    </geometry>
  </collision>
</link>

<link name="Part3_1">
  <inertial>
    <origin rpy="0 0 0" xyz="-0.00911464892336129 0.12606054498393937 5.551115123125783e-17"/>
    <mass value="0.1"/>
    <inertia ixx="0.00045" ixy="0.0" ixz="0.0" iyy="0.0004357" iyz="0.0" izz="0.0004369"/>
  </inertial>
  <visual>
    <origin rpy="0 0 0" xyz="0.001 -0.4505 -0.0475"/>
    <geometry>
      <mesh filename="package://spot_arm_description/meshes/Part3_1.stl" scale="0.001 0.001 0.001"/>
    </geometry>
    <material name="silver"/>
  </visual>
  <collision>
    <origin rpy="0 0 0" xyz="0.001 -0.4505 -0.0475"/>
    <geometry>
      <mesh filename="package://spot_arm_description/meshes/Part3_1.stl" scale="0.001 0.001 0.001"/>
    </geometry>
  </collision>
</link>

<link name="gripper_1">
  <inertial>
    <origin rpy="0 0 0" xyz="-8.366123908053191e-08 0.07051371901138614 0.017123167388316526"/>
    <mass value="0.1"/>
    <inertia ixx="0.00026875" ixy="0.0" ixz="-0.0" iyy="0.00025584" iyz="0.0" izz="0.00024338"/>
  </inertial>
  <visual>
    <origin rpy="0 0 0" xyz="0.0085 -0.77959 -0.0475"/>
    <geometry>
      <mesh filename="package://spot_arm_description/meshes/gripper_1.stl" scale="0.001 0.001 0.001"/>
    </geometry>
    <material name="silver"/>
  </visual>
  <collision>
    <origin rpy="0 0 0" xyz="0.0085 -0.77959 -0.0475"/>
    <geometry>
      <mesh filename="package://spot_arm_description/meshes/gripper_1.stl" scale="0.001 0.001 0.001"/>
    </geometry>
  </collision>
</link>

<link name="finger_1">
  <inertial>
    <origin rpy="0 0 0" xyz="0.8635899028063472 0.09862056591557622 0.00850232975194119"/>
    <mass value="0.1"/>
    <inertia ixx="0.0002724" ixy="0.0" ixz="-0.0" iyy="0.00224" iyz="0.0" izz="0.0002008"/>
  </inertial>
  <visual>
    <origin rpy="0 0 0" xyz="0.10297709 -0.823505 -0.0185"/>
    <geometry>
      <mesh filename="package://spot_arm_description/meshes/finger_1.stl" scale="0.001 0.001 0.001"/>
    </geometry>
    <material name="silver"/>
  </visual>
  <collision>
    <origin rpy="0 0 0" xyz="0.87709 -0.823505 -0.0185"/>
    <geometry>
      <mesh filename="package://spot_arm_description/meshes/finger_1.stl" scale="0.001 0.001 0.001"/>
    </geometry>
  </collision>
</link>

<link name="Part1_1">
  <inertial>
    <origin rpy="0 0 0" xyz="-0.0163095589512068 0.17540914221218962 0.0"/>
    <mass value="0.1"/>
    <inertia ixx="0.0002724" ixy="0.0" ixz="-0.0" iyy="0.000424" iyz="0.0" izz="0.0001008"/>
  </inertial>
  <visual>
    <origin rpy="0 0 0" xyz="-0.015 -0.0 -0.115"/>
    <geometry>
      <mesh filename="package://spot_arm_description/meshes/Part1_1.stl" scale="0.001 0.001 0.001"/>
    </geometry>
    <material name="silver"/>
  </visual>
  <collision>
    <origin rpy="0 0 0" xyz="-0.015 -0.0 -0.115"/>
    <geometry>
      <mesh filename="package://spot_arm_description/meshes/Part1_1.stl" scale="0.001 0.001 0.001"/>
    </geometry>
  </collision>
</link>

<link name="Part0_1">
  <inertial>
    <origin rpy="0 0 0" xyz="0.05071972800114364 -1.0308563411658574e-17 0.04676911608650795"/>
    <mass value="0.1"/>
    <inertia ixx="0.0002724" ixy="0.0" ixz="-0.0" iyy="0.000224" iyz="0.0" izz="0.0002008"/>
  </inertial>
  <visual>
    <origin rpy="0 0 0" xyz="-0.0 -0.0 -0.065"/>
    <geometry>
      <mesh filename="package://spot_arm_description/meshes/Part0_1.stl" scale="0.001 0.001 0.001"/>
    </geometry>
    <material name="silver"/>
  </visual>
  <collision>
    <origin rpy="0 0 0" xyz="-0.0 -0.0 -0.065"/>
    <geometry>
      <mesh filename="package://spot_arm_description/meshes/Part0_1.stl" scale="0.001 0.001 0.001"/>
    </geometry>
  </collision>
</link>

<link name="Part4_1">
  <inertial>
    <origin rpy="0 0 0" xyz="0.03954999709763633 0.03472006124891969 4.209155544249166e-08"/>
    <mass value="0.1"/>
    <inertia ixx="0.0001724" ixy="0.0" ixz="-0.0" iyy="0.000124" iyz="0.0" izz="0.0001008"/>
  </inertial>
  <visual>
    <origin rpy="0 0 0" xyz="0.0485 -0.69859 -0.0475"/>
    <geometry>
      <mesh filename="package://spot_arm_description/meshes/Part4_1.stl" scale="0.001 0.001 0.001"/>
    </geometry>
    <material name="silver"/>
  </visual>
  <collision>
    <origin rpy="0 0 0" xyz="0.0485 -0.69859 -0.0475"/>
    <geometry>
      <mesh filename="package://spot_arm_description/meshes/Part4_1.stl" scale="0.001 0.001 0.001"/>
    </geometry>
  </collision>
</link>

<link name="Part2_1">
  <inertial>
    <origin rpy="0 0 0" xyz="-0.015621881612358529 0.06665620790957599 -0.058074231003688394"/>
    <mass value="0.1"/>
    <inertia ixx="0.0002724" ixy="0.0" ixz="-0.0" iyy="0.000224" iyz="0.0" izz="0.0002008"/>
  </inertial>
  <visual>
    <origin rpy="0 0 0" xyz="-0.017 -0.3125 -0.115"/>
    <geometry>
      <mesh filename="package://spot_arm_description/meshes/Part2_1.stl" scale="0.001 0.001 0.001"/>
    </geometry>
    <material name="silver"/>
  </visual>
  <collision>
    <origin rpy="0 0 0" xyz="-0.017 -0.3125 -0.115"/>
    <geometry>
      <mesh filename="package://spot_arm_description/meshes/Part2_1.stl" scale="0.001 0.001 0.001"/>
    </geometry>
  </collision>
</link>

<joint name="Rev3" type="revolute">
  <origin rpy="0 0 0" xyz="-0.018 0.138 -0.0675"/>
  <parent link="Part2_1"/>
  <child link="Part3_1"/>
  <axis xyz="0.0 1.0 0.0"/>
  <limit effort="100" lower="-2.879793" upper="2.879793" velocity="100"/>
</joint>

<joint name="Rev6" type="revolute">
  <origin rpy="0 0 0" xyz="0.04 0.081 0.0"/>
  <parent link="Part4_1"/>
  <child link="gripper_1"/>
  <axis xyz="-0.0 1.0 0.0"/>
  <limit effort="100" lower="-2.96706" upper="2.96706" velocity="100"/>
</joint>

<joint name="Rev7" type="revolute">
  <origin rpy="0 0 0" xyz="-0.086859 0.043915 -0.029"/>
  <parent link="gripper_1"/>
  <child link="finger_1"/>
  <axis xyz="1.0 -0.0 0.0"/>
  <limit effort="100" lower="-1.396263" upper="0.349066" velocity="100"/>
</joint>

<joint name="Rev8" type="revolute">
  <origin rpy="0 0 0" xyz="0.015 0.0 0.05"/>
  <parent link="Part0_1"/>
  <child link="Part1_1"/>
  <axis xyz="-1.0 0.0 0.0"/>
  <limit effort="100" lower="-3.665191" upper="0.0" velocity="100"/>
</joint>

<joint name="Rev9" type="revolute">
  <origin rpy="0 0 1.57" xyz="0.0 0.0 0.065"/>
  <parent link="manipulator_base"/>
  <child link="Part0_1"/>
  <axis xyz="0.0 0.0 1.0"/>
  <limit effort="100" lower="-3.141593" upper="2.617994" velocity="100"/>
</joint>

<joint name="Rev10" type="revolute">
  <origin rpy="0 0 0" xyz="-0.0475 0.24809 0.0"/>
  <parent link="Part3_1"/>
  <child link="Part4_1"/>
  <axis xyz="1.0 0.0 0.0"/>
  <limit effort="100" lower="-1.570796" upper="1.570796" velocity="100"/>
</joint>

<joint name="Rev11" type="revolute">
  <origin rpy="3.14 0 0" xyz="0.002 0.3125 0.0"/>
  <parent link="Part1_1"/>
  <child link="Part2_1"/>
  <axis xyz="1.0 0.0 0.0"/>
  <limit effort="100" lower="0.0" upper="2.96706" velocity="100"/>
</joint>

</robot>
